Workbook
Name 共通フッタ: [1]設定!$C$5:$C$5
Name 排他制御: [1]設定!$C$6:$C$8

Sheet 改訂履歴
A1: テーブルレイアウト | N1: システム： | AI1: 作成日
N2: 請求書発行システム | AI2: 作成者
AI3: 更新日
A4: ﾌﾟﾛｼﾞｪｸﾄ名： | E4: 請求システム | N4: 英語名： | Q4: BillingSystem | AI4: 更新者
A6: フォーマット版数 | F6: 1 | N6: スキーマ | Q6: dbo
A8: 版数 | E8: 発行日 | K8: 担当者 | Q8: 変更内容

Sheet コードマスタ
A1: ・テーブルレイアウト | D1: =改訂履歴!N1 -> システム：
D2: =改訂履歴!N2 -> 請求書発行システム
A4: ﾌﾟﾛｼﾞｪｸﾄ名： | C4: =改訂履歴!E4 -> 請求システム | D4: 英語名： | E4: =改訂履歴!Q4 -> BillingSystem
A6: テーブル名（論理名） | C6: コードマスタ | F6: スキーマ | H6: =改訂履歴!Q6 -> dbo
A7: テーブルＩＤ（物理名） | C7: M_Code | F7: 排他制御
A9: № | B9: 項目名（論理名） | C9: 列名（物理名） | D9: 主キー | E9: データ型 | F9: 桁 | G9: 小数桁 | H9: NULL許可 | I9: 初期値 | J9: 項目概要 | L9: インデックス定義
A10: =ROW()-10 -> 0 | B10: 区分ID | C10: KindID | D10: ○ | E10: nvarchar | F10: 4 | L10: UNIQUE
A11: =ROW()-10 -> 1 | B11: コード | C11: Code | D11: ○ | E11: nvarchar | F11: 2 | L11: キー1
A12: =ROW()-10 -> 2 | B12: 名称 | C12: Name | E12: nvarchar | F12: 10 | L12: キー2
A13: =ROW()-10 -> 3 | B13: 表示順 | C13: DisplayNo | E13: int | L13: キー3
A14: =ROW()-10 -> 4 | B14: 登録ユーザー | C14: CreatUserID | E14: bigint | H14: ○ | L14: キー4
A15: =ROW()-10 -> 5 | B15: 登録日時 | C15: CreatDateTime | E15: datetime2 | H15: ○ | L15: キー5
A16: =ROW()-10 -> 6 | B16: 更新ユーザー | C16: UpdateUserID | E16: bigint | H16: ○ | L16: キー6
A17: =ROW()-10 -> 7 | B17: 更新日時 | C17: UpdateDateTime | E17: datetime2 | H17: ○ | L17: キー7
A18: =ROW()-10 -> 8 | L18: キー8
A19: =ROW()-10 -> 9 | L19: キー9
A20: =ROW()-10 -> 10 | L20: キー10
A21: =ROW()-10 -> 11
A22: =ROW()-10 -> 12
A23: =ROW()-10 -> 13
A24: =ROW()-10 -> 14
A25: =ROW()-10 -> 15
A26: =ROW()-10 -> 16
A27: =ROW()-10 -> 17
A28: =ROW()-10 -> 18
A29: =ROW()-10 -> 19
A30: =ROW()-10 -> 20
A31: =ROW()-10 -> 21
A32: =ROW()-10 -> 22
... A46: =ROW()-10 -> 36

Sheet 口座マスタ
A1: ・テーブルレイアウト | D1: =改訂履歴!N1 -> システム：
D2: =改訂履歴!N2 -> 請求書発行システム
A4: ﾌﾟﾛｼﾞｪｸﾄ名： | C4: =改訂履歴!E4 -> 請求システム | D4: 英語名： | E4: =改訂履歴!Q4 -> BillingSystem
A6: テーブル名（論理名） | C6: 自社銀行口座マスタ | F6: スキーマ | H6: =改訂履歴!Q6 -> dbo
A7: テーブルＩＤ（物理名） | C7: M_BankAccount | F7: 排他制御
A9: № | B9: 項目名（論理名） | C9: 列名（物理名） | D9: 主キー | E9: データ型 | F9: 桁 | G9: 小数桁 | H9: NULL許可 | I9: 初期値 | J9: 項目概要 | L9: インデックス定義
A10: =ROW()-10 -> 0 | B10: ID | C10: ID | D10: ○ | E10: bigint | L10: UNIQUE
A11: =ROW()-10 -> 1 | B11: 銀行コード | C11: BankCode | E11: nvarchar | F11: 5 | L11: キー1
A12: =ROW()-10 -> 2 | B12: 銀行名 | C12: BankName | E12: nvarchar | F12: 50 | L12: キー2
A13: =ROW()-10 -> 3 | B13: 支店コード | C13: BranchCode | E13: nvarchar | F13: 5 | L13: キー3
A14: =ROW()-10 -> 4 | B14: 支店名 | C14: BranchName | E14: nvarchar | F14: 50 | L14: キー4
A15: =ROW()-10 -> 5 | B15: 口座番号 | C15: AccountNo | E15: nvarchar | F15: 10 | L15: キー5
A16: =ROW()-10 -> 6 | B16: 名義 | C16: AccountName | E16: nvarchar | F16: 50 | L16: キー6
A17: =ROW()-10 -> 7 | B17: 削除フラグ | C17: DeleteFlag | E17: int | F17: 1 | I17: 0 | J17: 1:削除 | L17: キー7
A18: =ROW()-10 -> 8 | B18: 登録ユーザー | C18: CreatUserID | E18: bigint | H18: ○ | L18: キー8
A19: =ROW()-10 -> 9 | B19: 登録日時 | C19: CreatDateTime | E19: datetime2 | H19: ○ | L19: キー9
A20: =ROW()-10 -> 10 | B20: 更新ユーザー | C20: UpdateUserID | E20: bigint | H20: ○ | L20: キー10
A21: =ROW()-10 -> 11 | B21: 更新日時 | C21: UpdateDateTime | E21: datetime2 | H21: ○
A22: =ROW()-10 -> 12 | B22: LockVer | C22: LockVer | E22: int | I22: 0
A23: =ROW()-10 -> 13
A24: =ROW()-10 -> 14
A25: =ROW()-10 -> 15
A26: =ROW()-10 -> 16
A27: =ROW()-10 -> 17
A28: =ROW()-10 -> 18
A29: =ROW()-10 -> 19
A30: =ROW()-10 -> 20
A31: =ROW()-10 -> 21
A32: =ROW()-10 -> 22
A33: =ROW()-10 -> 23
A34: =ROW()-10 -> 24
... A41: =ROW()-10 -> 31

Sheet 会社マスタ
A1: ・テーブルレイアウト | D1: =改訂履歴!N1 -> システム：
D2: =改訂履歴!N2 -> 請求書発行システム
A4: ﾌﾟﾛｼﾞｪｸﾄ名： | C4: =改訂履歴!E4 -> 請求システム | D4: 英語名： | E4: =改訂履歴!Q4 -> BillingSystem
A6: テーブル名（論理名） | C6: 会社マスタ | F6: スキーマ | H6: =改訂履歴!Q6 -> dbo
A7: テーブルＩＤ（物理名） | C7: M_Company | F7: 排他制御
A9: № | B9: 項目名（論理名） | C9: 列名（物理名） | D9: 主キー | E9: データ型 | F9: 桁 | G9: 小数桁 | H9: NULL許可 | I9: 初期値 | J9: 項目概要 | L9: インデックス定義
A10: =ROW()-10 -> 0 | B10: ID | C10: ID | D10: ○ | E10: bigint | L10: UNIQUE
A11: =ROW()-10 -> 1 | B11: 会社名 | C11: CompanyName | E11: nvarchar | F11: 100 | L11: キー1
A12: =ROW()-10 -> 2 | B12: 郵便番号 | C12: PostNo | E12: nvarchar | F12: 10 | L12: キー2
A13: =ROW()-10 -> 3 | B13: 住所 | C13: Address | E13: nvarchar | F13: 125 | L13: キー3
A14: =ROW()-10 -> 4 | B14: 電話番号 | C14: Tel | E14: nvarchar | F14: 15 | L14: キー4
A15: =ROW()-10 -> 5 | B15: 消費税率 | C15: Tax | E15: decimal | F15: 5 | G15: 3 | L15: キー5
A16: =ROW()-10 -> 6 | B16: 端数 | C16: Fraction | E16: int | F16: 1 | I16: 3 | J16: 1:四捨五入 2:切り捨て 3:切り上げ | L16: キー6
A17: =ROW()-10 -> 7 | B17: インボイスNo | C17: InvoiceNo | E17: nvarchar | F17: 15 | H17: ○ | L17: キー7
A18: =ROW()-10 -> 8 | B18: 会社印ファイルID | C18: CompanySealID | E18: bigint | H18: ○ | L18: キー8
A19: =ROW()-10 -> 9 | B19: 会社印ファイル名 | C19: CompanySealName | E19: nvarchar | F19: 50 | H19: ○ | L19: キー9
A20: =ROW()-10 -> 10 | B20: 登録ユーザー | C20: CreatUserID | E20: bigint | H20: ○ | L20: キー10
A21: =ROW()-10 -> 11 | B21: 登録日時 | C21: CreatDateTime | E21: datetime2 | H21: ○
A22: =ROW()-10 -> 12 | B22: 更新ユーザー | C22: UpdateUserID | E22: bigint | H22: ○
A23: =ROW()-10 -> 13 | B23: 更新日時 | C23: UpdateDateTime | E23: datetime2 | H23: ○
A24: =ROW()-10 -> 14 | B24: LockVer | C24: LockVer | E24: int | I24: 0
A25: =ROW()-10 -> 15
A26: =ROW()-10 -> 16
A27: =ROW()-10 -> 17
A28: =ROW()-10 -> 18
A29: =ROW()-10 -> 19
A30: =ROW()-10 -> 20
A31: =ROW()-10 -> 21
A32: =ROW()-10 -> 22
A33: =ROW()-10 -> 23
A34: =ROW()-10 -> 24
A35: =ROW()-10 -> 25
A36: =ROW()-10 -> 26
... A41: =ROW()-10 -> 31

Sheet ユーザーマスタ
A1: ・テーブルレイアウト | D1: =改訂履歴!N1 -> システム：
D2: =改訂履歴!N2 -> 請求書発行システム
A4: ﾌﾟﾛｼﾞｪｸﾄ名： | C4: =改訂履歴!E4 -> 請求システム | D4: 英語名： | E4: =改訂履歴!Q4 -> BillingSystem
A6: テーブル名（論理名） | C6: ユーザーマスタ | F6: スキーマ | H6: =改訂履歴!Q6 -> dbo
A7: テーブルＩＤ（物理名） | C7: M_User | F7: 排他制御
A9: № | B9: 項目名（論理名） | C9: 列名（物理名） | D9: 主キー | E9: データ型 | F9: 桁 | G9: 小数桁 | H9: NULL許可 | I9: 初期値 | J9: 項目概要 | L9: インデックス定義
A10: =ROW()-10 -> 0 | B10: ID | C10: ID | D10: ○ | E10: bigint | L10: UNIQUE | M10: ○
A11: =ROW()-10 -> 1 | B11: ログインID | C11: LoginID | E11: nvarchar | F11: 20 | L11: キー1 | M11: LoginID
A12: =ROW()-10 -> 2 | B12: パスワード | C12: Password | E12: nvarchar | F12: 200 | H12: ○ | L12: キー2
A13: =ROW()-10 -> 3 | B13: 氏名 | C13: UserName | E13: nvarchar | F13: 50 | L13: キー3
A14: =ROW()-10 -> 4 | B14: カナ氏名 | C14: UserNameKana | E14: nvarchar | F14: 50 | H14: ○ | L14: キー4
A15: =ROW()-10 -> 5 | B15: 略称 | C15: UserShortName | E15: nvarchar | F15: 50 | L15: キー5
A16: =ROW()-10 -> 6 | B16: 部署 | C16: Department | E16: int | F16: 1 | H16: ○ | J16: 1:一般 2:承認社 3:管理者 | L16: キー6
A17: =ROW()-10 -> 7 | B17: 権限フラグ | C17: AuthorityFlag | E17: int | F17: 1 | J17: 9:管理者 1:一般ユーザー | L17: キー7
A18: =ROW()-10 -> 8 | B18: 捺印ファイルID | C18: SealFileID | E18: bigint | H18: ○ | L18: キー8
A19: =ROW()-10 -> 9 | B19: 捺印ファイル名 | C19: SealName | E19: nvarchar | F19: 50 | H19: ○ | L19: キー9
A20: =ROW()-10 -> 10 | B20: 備考 | C20: Note | E20: nvarchar | F20: 250 | H20: ○ | L20: キー10
A21: =ROW()-10 -> 11 | B21: 削除フラグ | C21: DeleteFlag | E21: int | F21: 1 | I21: 0 | J21: 1:削除
A22: =ROW()-10 -> 12 | B22: 登録ユーザー | C22: CreatUserID | E22: bigint | H22: ○
A23: =ROW()-10 -> 13 | B23: 登録日時 | C23: CreatDateTime | E23: datetime2 | H23: ○
A24: =ROW()-10 -> 14 | B24: 更新ユーザー | C24: UpdateUserID | E24: bigint | H24: ○
A25: =ROW()-10 -> 15 | B25: 更新日時 | C25: UpdateDateTime | E25: datetime2 | H25: ○
A26: =ROW()-10 -> 16 | B26: LockVer | C26: LockVer | E26: int | I26: 0
A27: =ROW()-10 -> 17
A28: =ROW()-10 -> 18
A29: =ROW()-10 -> 19
A30: =ROW()-10 -> 20
A31: =ROW()-10 -> 21
A32: =ROW()-10 -> 22
A33: =ROW()-10 -> 23
A34: =ROW()-10 -> 24
A35: =ROW()-10 -> 25
A36: =ROW()-10 -> 26
A37: =ROW()-10 -> 27
A38: =ROW()-10 -> 28
... A41: =ROW()-10 -> 31

Sheet 作業員マスタ
A1: ・テーブルレイアウト | D1: =改訂履歴!N1 -> システム：
D2: =改訂履歴!N2 -> 請求書発行システム
A4: ﾌﾟﾛｼﾞｪｸﾄ名： | C4: =改訂履歴!E4 -> 請求システム | D4: 英語名： | E4: =改訂履歴!Q4 -> BillingSystem
A6: テーブル名（論理名） | C6: 作業員マスタ | F6: スキーマ | H6: =改訂履歴!Q6 -> dbo
A7: テーブルＩＤ（物理名） | C7: M_Employee | F7: 排他制御
A9: № | B9: 項目名（論理名） | C9: 列名（物理名） | D9: 主キー | E9: データ型 | F9: 桁 | G9: 小数桁 | H9: NULL許可 | I9: 初期値 | J9: 項目概要 | L9: インデックス定義
A10: =ROW()-10 -> 0 | B10: ID | C10: ID | D10: ○ | E10: bigint | L10: UNIQUE
A11: =ROW()-10 -> 1 | B11: 氏名 | C11: Name | E11: nvarchar | F11: 50 | L11: キー1
A12: =ROW()-10 -> 2 | B12: カナ氏名 | C12: NameKana | E12: nvarchar | F12: 50 | H12: ○ | L12: キー2
A13: =ROW()-10 -> 3 | B13: 部署 | C13: Department | E13: nvarchar | F13: 50 | H13: ○ | L13: キー3
A14: =ROW()-10 -> 4 | B14: 内線Tel | C14: TelNo | E14: nvarchar | F14: 15 | H14: ○ | L14: キー4
A15: =ROW()-10 -> 5 | B15: 備考 | C15: Note | E15: nvarchar | F15: 250 | H15: ○ | L15: キー5
A16: =ROW()-10 -> 6 | B16: 削除フラグ | C16: DeleteFlag | E16: int | F16: 1 | I16: 0 | J16: 1:削除 | L16: キー6
A17: =ROW()-10 -> 7 | B17: 表示順 | C17: DisplayNo | E17: int | L17: キー7
A18: =ROW()-10 -> 8 | B18: 登録ユーザー | C18: CreatUserID | E18: bigint | H18: ○ | L18: キー8
A19: =ROW()-10 -> 9 | B19: 登録日時 | C19: CreatDateTime | E19: datetime2 | H19: ○ | L19: キー9
A20: =ROW()-10 -> 10 | B20: 更新ユーザー | C20: UpdateUserID | E20: bigint | H20: ○ | L20: キー10
A21: =ROW()-10 -> 11 | B21: 更新日時 | C21: UpdateDateTime | E21: datetime2 | H21: ○
A22: =ROW()-10 -> 12 | B22: LockVer | C22: LockVer | E22: int | I22: 0
A23: =ROW()-10 -> 13
A24: =ROW()-10 -> 14
A25: =ROW()-10 -> 15
A26: =ROW()-10 -> 16
A27: =ROW()-10 -> 17
A28: =ROW()-10 -> 18
A29: =ROW()-10 -> 19
A30: =ROW()-10 -> 20
A31: =ROW()-10 -> 21
A32: =ROW()-10 -> 22
A33: =ROW()-10 -> 23
A34: =ROW()-10 -> 24
... A41: =ROW()-10 -> 31

Sheet 社員プロジェクトマスタ
A1: ・テーブルレイアウト | D1: =改訂履歴!N1 -> システム：
D2: =改訂履歴!N2 -> 請求書発行システム
A4: ﾌﾟﾛｼﾞｪｸﾄ名： | C4: =改訂履歴!E4 -> 請求システム | D4: 英語名： | E4: =改訂履歴!Q4 -> BillingSystem
A6: テーブル名（論理名） | C6: 社員マスタ | F6: スキーマ | H6: =改訂履歴!Q6 -> dbo
A7: テーブルＩＤ（物理名） | C7: M_EmployeeProject | F7: 排他制御
A9: № | B9: 項目名（論理名） | C9: 列名（物理名） | D9: 主キー | E9: データ型 | F9: 桁 | G9: 小数桁 | H9: NULL許可 | I9: 初期値 | J9: 項目概要 | L9: インデックス定義
A10: =ROW()-10 -> 0 | B10: ID | C10: ID | D10: ○ | E10: bigint | L10: UNIQUE | M10: ○
A11: =ROW()-10 -> 1 | B11: 社員ID | C11: EmployeeID | E11: nvarchar | F11: 50 | L11: キー1 | M11: EmployeeID
A12: =ROW()-10 -> 2 | B12: プロジェクトID | C12: ProjectID | E12: nvarchar | F12: 50 | L12: キー2 | M12: ProjectID
A13: =ROW()-10 -> 3 | B13: プロジェクト開始日 | C13: StartDate | E13: date | L13: キー3
A14: =ROW()-10 -> 4 | B14: プロジェクト終了日 | C14: EndDate | E14: date | L14: キー4
A15: =ROW()-10 -> 5 | B15: 過不足精算フラグ | C15: SettlementFlag | E15: int | I15: 0 | L15: キー5
A16: =ROW()-10 -> 6 | B16: 過不足精算上限名 | C16: SettlementUpperLimitName | E16: varchar | F16: 10 | H16: ○ | L16: キー6
A17: =ROW()-10 -> 7 | B17: 過不足精算上限 | C17: SettlementUpperLimit | E17: int | H17: ○ | L17: キー7
A18: =ROW()-10 -> 8 | B18: 過不足精算下限名 | C18: SettlementLowerLimitName | E18: nvarchar | F18: 10 | H18: ○ | L18: キー8
A19: =ROW()-10 -> 9 | B19: 過不足精算下限 | C19: SettlementLowerLimit | E19: int | H19: ○ | L19: キー9
A20: =ROW()-10 -> 10 | B20: 基本月給（円） | C20: BasicAmount | E20: int | J20: 1:削除 | L20: キー10
A21: =ROW()-10 -> 11 | B21: 備考 | C21: Note | E21: nvarchar | F21: 500 | H21: ○
A22: =ROW()-10 -> 12 | B22: 削除フラグ | C22: DeleteFlag | E22: int | F22: 1 | I22: 0
A23: =ROW()-10 -> 13 | B23: 登録ユーザー | C23: CreatUserID | E23: bigint | H23: ○
A24: =ROW()-10 -> 14 | B24: 登録日時 | C24: CreatDateTime | E24: datetime2 | H24: ○
A25: =ROW()-10 -> 15 | B25: 更新ユーザー | C25: UpdateUserID | E25: bigint | H25: ○
A26: =ROW()-10 -> 16 | B26: 更新日時 | C26: UpdateDateTime | E26: datetime2 | H26: ○
A27: =ROW()-10 -> 17 | B27: LockVer | C27: LockVer | E27: int | I27: 0
A28: =ROW()-10 -> 18
A29: =ROW()-10 -> 19
A30: =ROW()-10 -> 20
A31: =ROW()-10 -> 21
A32: =ROW()-10 -> 22
A33: =ROW()-10 -> 23
A34: =ROW()-10 -> 24
A35: =ROW()-10 -> 25
A36: =ROW()-10 -> 26
A37: =ROW()-10 -> 27
A38: =ROW()-10 -> 28
A39: =ROW()-10 -> 29
... A41: =ROW()-10 -> 31

Sheet 請求先マスタ
A1: ・テーブルレイアウト | D1: =改訂履歴!N1 -> システム：
D2: =改訂履歴!N2 -> 請求書発行システム
A4: ﾌﾟﾛｼﾞｪｸﾄ名： | C4: =改訂履歴!E4 -> 請求システム | D4: 英語名： | E4: =改訂履歴!Q4 -> BillingSystem
A6: テーブル名（論理名） | C6: 請求先マスタ | F6: スキーマ | H6: =改訂履歴!Q6 -> dbo
A7: テーブルＩＤ（物理名） | C7: M_Customer | F7: 排他制御
A9: № | B9: 項目名（論理名） | C9: 列名（物理名） | D9: 主キー | E9: データ型 | F9: 桁 | G9: 小数桁 | H9: NULL許可 | I9: 初期値 | J9: 項目概要 | L9: インデックス定義
A10: =ROW()-10 -> 0 | B10: ID | C10: ID | D10: ○ | E10: bigint | L10: UNIQUE
A11: =ROW()-10 -> 1 | B11: 請求先名 | C11: CustomerName | E11: nvarchar | F11: 100 | L11: キー1
A12: =ROW()-10 -> 2 | B12: 請求先略称 | C12: CustomerShortName | E12: nvarchar | F12: 50 | H12: ○ | L12: キー2
A13: =ROW()-10 -> 3 | B13: 住所 | C13: Address | E13: nvarchar | F13: 100 | H13: ○ | L13: キー3
A14: =ROW()-10 -> 4 | B14: 電話番号 | C14: TelNo | E14: nvarchar | F14: 15 | H14: ○ | L14: キー4
A15: =ROW()-10 -> 5 | B15: 削除フラグ | C15: DeleteFlag | E15: int | F15: 1 | I15: 0 | J15: 1:削除 | L15: キー5
A16: =ROW()-10 -> 6 | B16: 表示順 | C16: DisplayNo | E16: int | L16: キー6
A17: =ROW()-10 -> 7 | B17: 登録ユーザー | C17: CreatUserID | E17: bigint | H17: ○ | L17: キー7
A18: =ROW()-10 -> 8 | B18: 登録日時 | C18: CreatDateTime | E18: datetime2 | H18: ○ | L18: キー8
A19: =ROW()-10 -> 9 | B19: 更新ユーザー | C19: UpdateUserID | E19: bigint | H19: ○ | L19: キー9
A20: =ROW()-10 -> 10 | B20: 更新日時 | C20: UpdateDateTime | E20: datetime2 | H20: ○ | J20: 支払区分マスタ | L20: キー10
A21: =ROW()-10 -> 11 | B21: LockVer | C21: LockVer | E21: int | I21: 0
A22: =ROW()-10 -> 12
A23: =ROW()-10 -> 13
A24: =ROW()-10 -> 14
A25: =ROW()-10 -> 15
A26: =ROW()-10 -> 16
A27: =ROW()-10 -> 17
A28: =ROW()-10 -> 18
A29: =ROW()-10 -> 19
A30: =ROW()-10 -> 20
A31: =ROW()-10 -> 21
A32: =ROW()-10 -> 22
A33: =ROW()-10 -> 23
... A41: =ROW()-10 -> 31

Sheet 部署マスタ
A1: ・テーブルレイアウト | D1: =改訂履歴!N1 -> システム：
D2: =改訂履歴!N2 -> 請求書発行システム
A4: ﾌﾟﾛｼﾞｪｸﾄ名： | C4: =改訂履歴!E4 -> 請求システム | D4: 英語名： | E4: =改訂履歴!Q4 -> BillingSystem
A6: テーブル名（論理名） | C6: 部署マスタ | F6: スキーマ | H6: =改訂履歴!Q6 -> dbo
A7: テーブルＩＤ（物理名） | C7: M_Department | F7: 排他制御
A9: № | B9: 項目名（論理名） | C9: 列名（物理名） | D9: 主キー | E9: データ型 | F9: 桁 | G9: 小数桁 | H9: NULL許可 | I9: 初期値 | J9: 項目概要 | L9: インデックス定義
A10: =ROW()-10 -> 0 | C10: ID | D10: ○ | E10: bigint | L10: UNIQUE
A11: =ROW()-10 -> 1 | B11: 請求先ID | C11: CustomeID | E11: bigint | L11: キー1
A12: =ROW()-10 -> 2 | B12: 部署名 | C12: DepartmentName | E12: nvarchar | F12: 100 | L12: キー2
A13: =ROW()-10 -> 3 | B13: 部署略称 | C13: DepartmentShortName | E13: nvarchar | F13: 100 | L13: キー3
A14: =ROW()-10 -> 4 | B14: 電話番号 | C14: TelNo | E14: nvarchar | F14: 15 | L14: キー4
A15: =ROW()-10 -> 5 | B15: 削除フラグ | C15: DeleteFlag | E15: int | F15: 1 | I15: 0 | J15: 1:削除 | L15: キー5
A16: =ROW()-10 -> 6 | B16: 表示順 | C16: DisplayNo | E16: int | L16: キー6
A17: =ROW()-10 -> 7 | B17: 登録ユーザー | C17: CreatUserID | E17: bigint | H17: ○ | L17: キー7
A18: =ROW()-10 -> 8 | B18: 登録日時 | C18: CreatDateTime | E18: datetime2 | H18: ○ | L18: キー8
A19: =ROW()-10 -> 9 | B19: 更新ユーザー | C19: UpdateUserID | E19: bigint | H19: ○ | L19: キー9
A20: =ROW()-10 -> 10 | B20: 更新日時 | C20: UpdateDateTime | E20: datetime2 | H20: ○ | L20: キー10
A21: =ROW()-10 -> 11 | B21: LockVer | C21: LockVer | E21: int | I21: 0
A22: =ROW()-10 -> 12
A23: =ROW()-10 -> 13
A24: =ROW()-10 -> 14
A25: =ROW()-10 -> 15
A26: =ROW()-10 -> 16
A27: =ROW()-10 -> 17
A28: =ROW()-10 -> 18
A29: =ROW()-10 -> 19
A30: =ROW()-10 -> 20
A31: =ROW()-10 -> 21
A32: =ROW()-10 -> 22
A33: =ROW()-10 -> 23
... A41: =ROW()-10 -> 31

Sheet プロジェクトマスタ
A1: ・テーブルレイアウト | D1: =改訂履歴!N1 -> システム：
D2: =改訂履歴!N2 -> 請求書発行システム
A4: ﾌﾟﾛｼﾞｪｸﾄ名： | C4: =改訂履歴!E4 -> 請求システム | D4: 英語名： | E4: =改訂履歴!Q4 -> BillingSystem
A6: テーブル名（論理名） | C6: プロジェクトマスタ | F6: スキーマ | H6: =改訂履歴!Q6 -> dbo
A7: テーブルＩＤ（物理名） | C7: M_Project | F7: 排他制御
A9: № | B9: 項目名（論理名） | C9: 列名（物理名） | D9: 主キー | E9: データ型 | F9: 桁 | G9: 小数桁 | H9: NULL許可 | I9: 初期値 | J9: 項目概要 | L9: インデックス定義
A10: =ROW()-10 -> 0 | C10: ID | D10: ○ | E10: bigint | L10: UNIQUE
A11: =ROW()-10 -> 1 | B11: 請求先ID | C11: CustomeID | E11: bigint | L11: キー1
A12: =ROW()-10 -> 2 | B12: 発注書番号 | C12: OrderNo | E12: nvarchar | F12: 50 | H12: ○ | L12: キー2
A13: =ROW()-10 -> 3 | B13: 請求No | C13: BillingNo | E13: nvarchar | F13: 10 | H13: ○ | L13: キー3
A14: =ROW()-10 -> 4 | B14: 作業名 | C14: ProjectName | E14: nvarchar | F14: 100 | H14: ○ | L14: キー4
A15: =ROW()-10 -> 5 | B15: 作業内容 | C15: ProjectContent | E15: nvarchar | F15: 150 | H15: ○ | L15: キー5
A16: =ROW()-10 -> 6 | B16: 作業場所 | C16: ProjectAdd | E16: nvarchar | F16: 100 | H16: ○ | L16: キー6
A17: =ROW()-10 -> 7 | B17: 納品成果物 | C17: Deliverables | E17: nvarchar | F17: 100 | H17: ○ | L17: キー7
A18: =ROW()-10 -> 8 | B18: 支払区分 | C18: PaymentType | E18: int | J18: 支払区分マスタ | L18: キー8
A19: =ROW()-10 -> 9 | B19: 削除フラグ | C19: DeleteFlag | E19: int | F19: 1 | I19: 0 | J19: 1:削除 | L19: キー9
A20: =ROW()-10 -> 10 | B20: 表示順 | C20: DisplayNo | E20: int | L20: キー10
A21: =ROW()-10 -> 11 | B21: 登録ユーザー | C21: CreatUserID | E21: bigint | H21: ○
A22: =ROW()-10 -> 12 | B22: 登録日時 | C22: CreatDateTime | E22: datetime2 | H22: ○
A23: =ROW()-10 -> 13 | B23: 更新ユーザー | C23: UpdateUserID | E23: bigint | H23: ○
A24: =ROW()-10 -> 14 | B24: 更新日時 | C24: UpdateDateTime | E24: datetime2 | H24: ○
A25: =ROW()-10 -> 15 | B25: LockVer | C25: LockVer | E25: int | I25: 0
A26: =ROW()-10 -> 16
A27: =ROW()-10 -> 17
A28: =ROW()-10 -> 18
A29: =ROW()-10 -> 19
A30: =ROW()-10 -> 20
A31: =ROW()-10 -> 21
A32: =ROW()-10 -> 22
A33: =ROW()-10 -> 23
A34: =ROW()-10 -> 24
A35: =ROW()-10 -> 25
A36: =ROW()-10 -> 26
A37: =ROW()-10 -> 27
... A41: =ROW()-10 -> 31

Sheet 支払区分
A1: ・テーブルレイアウト | D1: =改訂履歴!N1 -> システム：
D2: =改訂履歴!N2 -> 請求書発行システム
A4: ﾌﾟﾛｼﾞｪｸﾄ名： | C4: =改訂履歴!E4 -> 請求システム | D4: 英語名： | E4: =改訂履歴!Q4 -> BillingSystem
A6: テーブル名（論理名） | C6: 支払区分 | F6: スキーマ | H6: =改訂履歴!Q6 -> dbo
A7: テーブルＩＤ（物理名） | C7: M_PaymentType | F7: 排他制御
A9: № | B9: 項目名（論理名） | C9: 列名（物理名） | D9: 主キー | E9: データ型 | F9: 桁 | G9: 小数桁 | H9: NULL許可 | I9: 初期値 | J9: 項目概要 | L9: インデックス定義
A10: =ROW()-10 -> 0 | C10: ID | D10: ○ | E10: bigint | L10: UNIQUE
A11: =ROW()-10 -> 1 | B11: 支払区分 | C11: Type | E11: int | L11: キー1
A12: =ROW()-10 -> 2 | B12: 支払区分名 | C12: PaymentTypeName | E12: nvarchar | F12: 100 | L12: キー2
A13: =ROW()-10 -> 3 | B13: 加算日 | C13: AddDays | E13: int | F13: 3 | L13: キー3
A14: =ROW()-10 -> 4 | B14: 削除フラグ | C14: DeleteFlag | E14: int | F14: 1 | I14: 0 | J14: 1:削除 | L14: キー4
A15: =ROW()-10 -> 5 | B15: 表示順 | C15: DisplayNo | E15: int | L15: キー5
A16: =ROW()-10 -> 6 | B16: 登録ユーザー | C16: CreatUserID | E16: bigint | H16: ○ | L16: キー6
A17: =ROW()-10 -> 7 | B17: 登録日時 | C17: CreatDateTime | E17: datetime2 | H17: ○ | L17: キー7
A18: =ROW()-10 -> 8 | B18: 更新ユーザー | C18: UpdateUserID | E18: bigint | H18: ○ | L18: キー8
A19: =ROW()-10 -> 9 | B19: 更新日時 | C19: UpdateDateTime | E19: datetime2 | H19: ○ | L19: キー9
A20: =ROW()-10 -> 10 | B20: LockVer | C20: LockVer | E20: int | I20: 0 | L20: キー10
A21: =ROW()-10 -> 11
A22: =ROW()-10 -> 12
A23: =ROW()-10 -> 13
A24: =ROW()-10 -> 14
A25: =ROW()-10 -> 15
A26: =ROW()-10 -> 16
A27: =ROW()-10 -> 17
A28: =ROW()-10 -> 18
A29: =ROW()-10 -> 19
A30: =ROW()-10 -> 20
A31: =ROW()-10 -> 21
A32: =ROW()-10 -> 22
... A41: =ROW()-10 -> 31

Sheet 請求書
A1: ・テーブルレイアウト | D1: =改訂履歴!N1 -> システム：
D2: =改訂履歴!N2 -> 請求書発行システム
A4: ﾌﾟﾛｼﾞｪｸﾄ名： | C4: =改訂履歴!E4 -> 請求システム | D4: 英語名： | E4: =改訂履歴!Q4 -> BillingSystem
A6: テーブル名（論理名） | C6: 請求書 | F6: スキーマ | H6: =改訂履歴!Q6 -> dbo
A7: テーブルＩＤ（物理名） | C7: T_Billing | F7: 排他制御
A9: № | B9: 項目名（論理名） | C9: 列名（物理名） | D9: 主キー | E9: データ型 | F9: 桁 | G9: 小数桁 | H9: NULL許可 | I9: 初期値 | J9: 項目概要 | L9: インデックス定義
A10: =ROW()-10 -> 0 | C10: ID | D10: ○ | E10: bigint | L10: UNIQUE
A11: =ROW()-10 -> 1 | B11: 請求日（発行日） | C11: BillingDate | E11: date | L11: キー1
A12: =ROW()-10 -> 2 | B12: 請求No | C12: BillingNo | E12: nvarchar | F12: 20 | L12: キー2
A13: =ROW()-10 -> 3 | B13: 請求No枝番 | C13: BranchNo | E13: int | F13: 3 | L13: キー3
A14: =ROW()-10 -> 4 | B14: 請求開始日 | C14: BillingFromDate | E14: date | L14: キー4
A15: =ROW()-10 -> 5 | B15: 請求終了日 | C15: BillingToDate | E15: date | L15: キー5
A16: =ROW()-10 -> 6 | B16: 請求先ID | C16: CustomeID | E16: bigint | L16: キー6
A17: =ROW()-10 -> 7 | B17: 請求先名 | C17: CustomerName | E17: nvarchar | F17: 100 | L17: キー7
A18: =ROW()-10 -> 8 | B18: 部署名 | C18: DepartmentName | E18: nvarchar | F18: 100 | H18: ○ | L18: キー8
A19: =ROW()-10 -> 9 | B19: 発注書番号 | C19: OrderNo | E19: nvarchar | F19: 50 | H19: ○ | L19: キー9
A20: =ROW()-10 -> 10 | B20: 作業名 | C20: ProjectName | E20: nvarchar | F20: 100 | L20: キー10
A21: =ROW()-10 -> 11 | B21: 作業内容 | C21: ProjectContent | E21: nvarchar | F21: 150
A22: =ROW()-10 -> 12 | B22: 作業場所 | C22: ProjectAdd | E22: nvarchar | F22: 100
A23: =ROW()-10 -> 13 | B23: 納品成果物 | C23: Deliverables | E23: nvarchar | F23: 100
A24: =ROW()-10 -> 14 | B24: 支払区分 | C24: PaymentType | E24: int
A25: =ROW()-10 -> 15 | B25: 支払区分名 | C25: PaymentTypeName | E25: nvarchar | F25: 100
A26: =ROW()-10 -> 16 | B26: 支払日 | C26: PaymentDate | E26: date
A27: =ROW()-10 -> 17 | B27: 請求金額(税抜) | C27: BillingAmount | E27: int
A28: =ROW()-10 -> 18 | B28: 消費税率 | C28: Tax | E28: decimal | F28: 5 | G28: 3
A29: =ROW()-10 -> 19 | B29: 消費税 | C29: BillingTax | E29: int
A30: =ROW()-10 -> 20 | B30: 交通費 | C30: TransportationAmount | E30: int
A31: =ROW()-10 -> 21 | B31: 請求金額 | C31: BillingTotal | E31: int | J31: 1:削除
A32: =ROW()-10 -> 22 | B32: 口座ID | C32: BankAccountID | E32: bigint
A33: =ROW()-10 -> 23 | B33: 削除フラグ | C33: DeleteFlag | E33: int | F33: 1 | I33: 0
A34: =ROW()-10 -> 24 | B34: 担当者ID | C34: ManagerID | E34: bigint
A35: =ROW()-10 -> 25 | B35: 請求書ファイルID | C35: PDFFileID | E35: bigint | H35: ○ | J35: 0：作成中 1：承認待ち 2:承認済 3:完了 9:送付済
A36: =ROW()-10 -> 26 | B36: ステータス | C36: Status | E36: int | F36: 1
A37: =ROW()-10 -> 27 | B37: 承認者ID | C37: ApproverID | E37: bigint | H37: ○
A38: =ROW()-10 -> 28 | B38: 承認日時 | C38: ApprovalDateTime | E38: datetime | H38: ○
A39: =ROW()-10 -> 29 | B39: 完了者ID | C39: CompleterID | E39: bigint | H39: ○
A40: =ROW()-10 -> 30 | B40: 完了日時 | C40: CompletionDateTime | E40: datetime | H40: ○
A41: =ROW()-10 -> 31 | B41: 送付者ID | C41: SenderID | E41: bigint | H41: ○
A42: =ROW()-10 -> 32 | B42: 送付日時 | C42: DeliveryDateTime | E42: datetime | H42: ○
A43: =ROW()-10 -> 33 | B43: 登録ユーザー | C43: CreatUserID | E43: bigint | H43: ○
...

Sheet 請求書明細
A1: ・テーブルレイアウト | D1: =改訂履歴!N1 -> システム：
D2: =改訂履歴!N2 -> 請求書発行システム
A4: ﾌﾟﾛｼﾞｪｸﾄ名： | C4: =改訂履歴!E4 -> 請求システム | D4: 英語名： | E4: =改訂履歴!Q4 -> BillingSystem
A6: テーブル名（論理名） | C6: 請求書明細 | F6: スキーマ | H6: =改訂履歴!Q6 -> dbo
A7: テーブルＩＤ（物理名） | C7: T_BillingDetail | F7: 排他制御
A9: № | B9: 項目名（論理名） | C9: 列名（物理名） | D9: 主キー | E9: データ型 | F9: 桁 | G9: 小数桁 | H9: NULL許可 | I9: 初期値 | J9: 項目概要 | L9: インデックス定義
A10: =ROW()-10 -> 0 | C10: ID | D10: ○ | E10: bigint | L10: UNIQUE | M10: ○
A11: =ROW()-10 -> 1 | B11: 請求書ID | C11: BillingID | E11: bigint | L11: キー1 | M11: BillingID
A12: =ROW()-10 -> 2 | B12: 社員ID | C12: EmployeeID | E12: bigint | L12: キー2 | M12: EmployeeID
A13: =ROW()-10 -> 3 | B13: 社員氏名 | C13: EmployeeName | E13: nvarchar | F13: 50 | L13: キー3
A14: =ROW()-10 -> 4 | B14: 過不足精算フラグ | C14: SettlementFlag | E14: int | I14: 0 | L14: キー4
A15: =ROW()-10 -> 5 | B15: 勤務時間 | C15: WorkingHours | E15: int | L15: キー5
A16: =ROW()-10 -> 6 | B16: 基本月給（円） | C16: BasicAmount | E16: int | L16: キー6
A17: =ROW()-10 -> 7 | B17: 過不足精算下限名 | C17: LowerLimitName | E17: nvarchar | F17: 10 | H17: ○ | L17: キー7
A18: =ROW()-10 -> 8 | B18: 過不足精算下限単価 | C18: LowerLimitUnit | E18: int | H18: ○ | L18: キー8
A19: =ROW()-10 -> 9 | B19: 過不足精算下限金額 | C19: LowerLimitAmount | E19: int | H19: ○ | L19: キー9
A20: =ROW()-10 -> 10 | B20: 過不足精算上限名 | C20: UpperLimitName | E20: nvarchar | F20: 10 | H20: ○ | L20: キー10
A21: =ROW()-10 -> 11 | B21: 過不足精算上限単価 | C21: UpperLimitUnit | E21: int | H21: ○
A22: =ROW()-10 -> 12 | B22: 過不足精算上限金額 | C22: UpperLimitAmount | E22: int | H22: ○
A23: =ROW()-10 -> 13 | B23: 請求金額 | C23: BillingAmount | E23: int
A24: =ROW()-10 -> 14 | B24: 交通費 | C24: TransportationAmount | E24: int
A25: =ROW()-10 -> 15 | B25: 削除フラグ | C25: DeleteFlag | E25: int | F25: 1 | I25: 0 | J25: 1:削除
A26: =ROW()-10 -> 16 | B26: 登録ユーザー | C26: CreatUserID | E26: bigint | H26: ○
A27: =ROW()-10 -> 17 | B27: 登録日時 | C27: CreatDateTime | E27: datetime2 | H27: ○
A28: =ROW()-10 -> 18 | B28: 更新ユーザー | C28: UpdateUserID | E28: bigint | H28: ○
A29: =ROW()-10 -> 19 | B29: 更新日時 | C29: UpdateDateTime | E29: datetime2 | H29: ○
A30: =ROW()-10 -> 20 | B30: LockVer | C30: LockVer | E30: int | I30: 0
A31: =ROW()-10 -> 21
A32: =ROW()-10 -> 22
A33: =ROW()-10 -> 23
A34: =ROW()-10 -> 24
A35: =ROW()-10 -> 25
A36: =ROW()-10 -> 26
A37: =ROW()-10 -> 27
A38: =ROW()-10 -> 28
A39: =ROW()-10 -> 29
A40: =ROW()-10 -> 30
A41: =ROW()-10 -> 31
A42: =ROW()-10 -> 32
... A46: =ROW()-10 -> 36

Sheet ファイルデータ
A1: ・テーブルレイアウト | D1: =改訂履歴!N1 -> システム：
D2: =改訂履歴!N2 -> 請求書発行システム
A4: ﾌﾟﾛｼﾞｪｸﾄ名： | C4: =改訂履歴!E4 -> 請求システム | D4: 英語名： | E4: =改訂履歴!Q4 -> BillingSystem
A6: テーブル名（論理名） | C6: ファイルデータ | F6: スキーマ | H6: =改訂履歴!Q6 -> dbo
A7: テーブルＩＤ（物理名） | C7: T_File | F7: 排他制御
A9: № | B9: 項目名（論理名） | C9: 列名（物理名） | D9: 主キー | E9: データ型 | F9: 桁 | G9: 小数桁 | H9: NULL許可 | I9: 初期値 | J9: 項目概要 | L9: インデックス定義
A10: =ROW()-10 -> 0 | B10: ID | C10: ID | D10: ○ | E10: bigint | L10: UNIQUE
A11: =ROW()-10 -> 1 | B11: ファイルデータ | C11: File | E11: varbinary | F11: Max | L11: キー1
A12: =ROW()-10 -> 2 | B12: 登録ユーザー | C12: CreatUserID | E12: bigint | H12: ○ | L12: キー2
A13: =ROW()-10 -> 3 | B13: 登録日時 | C13: CreatDateTime | E13: datetime2 | H13: ○ | L13: キー3
A14: =ROW()-10 -> 4 | B14: 更新ユーザー | C14: UpdateUserID | E14: bigint | H14: ○ | L14: キー4
A15: =ROW()-10 -> 5 | B15: 更新日時 | C15: UpdateDateTime | E15: datetime2 | H15: ○ | L15: キー5
A16: =ROW()-10 -> 6 | B16: LockVer | C16: LockVer | E16: int | I16: 0 | L16: キー6
A17: =ROW()-10 -> 7 | L17: キー7
A18: =ROW()-10 -> 8 | L18: キー8
A19: =ROW()-10 -> 9 | L19: キー9
A20: =ROW()-10 -> 10 | L20: キー10
A21: =ROW()-10 -> 11
A22: =ROW()-10 -> 12
A23: =ROW()-10 -> 13
A24: =ROW()-10 -> 14
A25: =ROW()-10 -> 15
A26: =ROW()-10 -> 16
A27: =ROW()-10 -> 17
A28: =ROW()-10 -> 18
A29: =ROW()-10 -> 19
A30: =ROW()-10 -> 20
A31: =ROW()-10 -> 21
A32: =ROW()-10 -> 22
... A41: =ROW()-10 -> 31

Sheet 説明
A2: テーブルレイアウトシート
B3: 型 | C3: 説明 | D3: ストレージ上のサイズ
A4: 整数型 | B4: bigint | C4: -2^63 (-9,223,372,036,854,775,808) ～ 2^63-1 (9,223,372,036,854,775,807)の範囲の整数型 | D4: 8
B5: int | C5: -2^31 (-2,147,483,648) ～ 2^31-1 (2,147,483,647)の範囲の整数型 | D5: 4
B6: smallint | C6: -2^15 (-32,768) ～ 2^15-1 (32,767)の範囲の整数型 | D6: 2
B7: tinyint | C7: 0 ～ 255の範囲の整数型 | D7: 1
B8: bit | C8: 1、または0の範囲の整数型
B9: decimal | C9: decimal [(p[ ,s])] 固定長の有効桁数と小数点以下桁数を持つ数値 | D9: 有効桁数により変動
B10: numeric | C10: numeric [(p[ ,s])]
A11: 浮動小数点型 | B11: float | C11: – 1.79E+308 ～ -2.23E-308、0、および 2.23E-308 ～ 1.79E+308の範囲の浮動小数点型n：有効桁数。1～53 (規定値53) | D11: 有効桁数により変動
B12: real | C12: – 3.40E+38 ～ -1.18E-38、0、および 1.18E-38 ～ 3.40E+38の範囲の浮動小数点型 | D12: 4
A13: 通貨型 | B13: money | C13: -922,337,203,685,477.5808 ～ 922,337,203,685,477.5807の範囲の通貨型表している通貨単位の 10,000 分の 1 までの精度を持ちます。 | D13: 8
B14: smallmoney | C14: – 214,748.3648 ～ 214,748.3647の範囲の通貨型表している通貨単位の 10,000 分の 1 までの精度を持ちます。 | D14: 4
A15: 日付型 | B15: date | C15: 0001-01-01～9999-12-31の範囲の日付型 | D15: 3
B16: time | C16: 00:00:00.0000000 ～ 23:59:59.9999999の範囲の時間型p：秒の小数点以下の有効桁数。0～7 (規定値7) | D16: 有効桁数が規定値のとき5
B17: datetime | C17: 日付が 1753年1月1日～9999年12月31日、時刻が00:00:00～23:59:59.997の範囲の日付型 | D17: 8
B18: datetime2 | C18: 日付が 0001-01-01 ～ 9999-12-31、時刻が00:00:00 ～ 23:59:59.9999999の範囲の日付型p：秒の小数点以下の有効桁数。0～7 (規定値7) | D18: 有効桁数により変動
B19: smalldatetime | C19: 日付が 1900-01-01 ～ 2079-06-06、時刻が00:00:00 ～ 23:59:59の範囲の日付型秒数は常にゼロ (:00) で、1 秒未満の秒を持ちません。 | D19: 4
B20: datetimeoffset | C20: 日付が 0001-01-01 ～ 9999-12-31、時刻が00:00:00 ～ 23:59:59.9999999の範囲のタイム ゾーンを認識する日付型タイムゾーンの範囲は-14:00 ～ +14:00。 | D20: 有効桁数が規定値のとき10
A21: 文字列型 | B21: char | C21: Unicode ではない固定長の文字列型n：桁数。1 ～ 8,000 | D21: nバイト
B22: varchar | C22: Unicode ではない可変長の文字列型n：桁数。1 ～ 8,000 | D22: 入力したデータサイズ+2バイト
B23: text | C23: Unicode ではない可変長の文字列型 | D23: サーバー コード ページが 2 バイト文字を使用する場合、格納サイズは、そのまま 2,147,483,647 バイト
A24: Unicode 文字型 | B24: nchar | C24: Unicode の固定長の文字列型n：桁数。1 ～ 4,000 | D24: n×2バイト
B25: nvarchar | C25: Unicode の可変長の文字列型n：桁数。1 ～ 4,000 | D25: 入力したデータサイズ×2+2バイト
B26: ntext | C26: 2^30 – 1 (1,073,741,823) 文字以内の可変長の Unicode データを格納するデータ型 | D26: 入力したデータサイズ×2バイト
A27: バイナリ型 | B27: binary | C27: 固定長のバイナリ データn：桁数。1 ～ 8,000 | D27: nバイト
B28: varbinary | C28: 可変長のバイナリ データn：桁数。1 ～ 8,000 | D28: 入力したデータサイズ+2バイト
B29: image | C29: 0 ～ 2^31-1 (2,147,483,647) バイトの可変長のバイナリ型
